Workbook
Name _Hlk178865892: Instructions!$E$57
Name AprPie: 'PIE Tracker'!$V$3:$Z$34
Name FEBpie: 'PIE Tracker'!$H$3:$M$34
Name JANPIE: 'PIE Tracker'!$A$3:$F$34
Name MARPIE: 'PIE Tracker'!$O$3:$T$34

Sheet Goals & Fees
A1: This sheet is protected, input details in the blue outlined cells.
A2: Yearly Goals and Fees
C3: 1. Enter Your Gross Commissions Income Goal | J3: Annual Gross Commission GOAL
D4: Do not leave blank. Calculations depend on this number. | L4: 200000
C8: 2. Do you pay a franchise fee on each transaction? | J8: Franchise Fee
C9: If yes, fill in the flat fee to be deducted from each transaction or % deducted from each transaction.
D10: Leave blank if no franchise fee. | L10: Flat Fee | N10: Franchise Fee as a %.
C12: Is there a franchise fees cap? | J12: Franchise Fee Cap
C13: If you contribute franchise fees from each transaction until you have reached a specific threshold, the answer is yes. Enter your "franchise fee cap" here.
D14: Leave blank if no franchise fee and/or no franchise fee cap.
C17: 3. Do you pay a marketing fee on each transaction? | J17: Marketing Fee
C18: If yes, fill in the flat fee to be deducted from each transaction or % deducted from each transaction.
D19: Leave blank if no per transaction marketing fee. | L19: Flat Fee | N19: Marketing Fee as a %.
C21: Is there a "marketing fee cap"? | J21: Marketing Fee Cap
C22: If you contribute marketing fees from each transaction until you have reached a specific threshold, the answer is yes. Enter your "marketing fee cap" here.
D23: Leave blank if no marketing fee and/or no marketing fee cap.
A26: 4. Commission Structure -
A27: Is your split dependent on an Office Cap or Fair Share? | K27: Do you have a progressive split structure?
L28: If your split is on a sliding scale, sometimes referred to as a progressive split, based on total earned income year to date, enter the upper end of each of the tiers below along with the corresponding split as a %.
B29: Enter office cap or fair share here. | D29: Office Cap / Fair Share
A30: For example, if you have a fair share or office cap of $40,000. You may start the year with a 50/50 split until you have paid the office $40,000. Once you have met your fair share/office cap, your split would change. | E30: 8000 | K30: % of gross commission | N30: Fill-In Earned Income Tiers .
N32: 0 | P32: to
A33: What is your starting split at the beginning of each year?
E34: Starting Split as a % | N34: =Q32+1 -> 1 | P34: to
B35: Enter this as your percentage. | F35: 0.68 | K35: Must contain a value greater than 0 | Q35: Leave blank if last tier.
A36: For example, if you are on a 60/40 split, where you receive 60% and 40% goes to the office, enter 60%. | F36: Must enter a value. | N36: =Q34+1 -> 1 | P36: to
K37: Must contain a value greater than 0 | Q37: Leave blank if last tier.
A38: What is your split after office cap/fair share has been met? | N38: =Q36+1 -> 1 | P38: to
E39: Secondary Split as a % | K39: Enter 100% unless split is applied | Q39: Leave blank if last tier.
B40: Enter this as your percentage. | F40: 0.85 | N40: =Q38+1 -> 1 | P40: to
A41: For example, if you are on a 80/20 split, where you receive 80% and 20% goes to the office, enter 80%. | K41: Enter 100% unless split is applied | Q41: Leave blank if last tier.
E42: Note: If you go to 100% commission once you meet your cap/fair share, enter 100% here. | N42: =Q40+1 -> 1 | P42: +
K43: Enter 100% unless split is applied | Q43: **Blue outlined boxes indicate a value is needed.

Sheet Business Tracker
K1: 2025 Business Tracker
A2: "Warm" Prospects | I2: "Hot" and Active Prospects | Q2: Under Contract | Y2: Closed Transactions
AC3: Buy
AC4: Sell
B5: Contact Date (mm/dd) | C5: Client Name | D5: P/P Rating | E5: Estimated Sales Price | F5: % | G5: Potential Gross Commission Income | J5: Contact Date (mm/dd) | K5: Client Name | L5: P/P Rating | M5: Estimated Sales Price | N5: % | O5: Potential Gross Commission Income | Q5: Client Name | R5: Notes: Buy/Sell, signed agreements, status, updates | S5: Closing date | T5: For PIE Summary | U5: Sales Price | V5: % | W5: Estimated GCI | Z5: Closing date | AA5: Closing Month-for PIE Summary | AB5: Client Name | AC5: Buy/ Sell | AD5: Sales Price | AE5: % | AF5: Gross Commission Income
B6: 45895 | C6: Dennis Greza | E6: 650000 | F6: 0.03 | G6: =E6*F6 -> 19500 | J6: 45945 | K6: Andrew Papantoniou | M6: 600000 | N6: 0.03 | O6: =N6*M6 -> 18000 | Q6: Karla & Daniel | R6: rent | S6: 46006 | U6: 2350 | V6: 0 | W6: =U6*V6 -> 0 | Z6: =IF('Closed Transactions'!A3="", "",'Closed Transactions'!A3) -> 45667 | AA6: =MONTH(Z6) -> 1 | AB6: =IF('Closed Transactions'!F3="","",'Closed Transactions'!F3) -> Kevin Zhao | AC6: =IF(AND('Closed Transactions'!B3="",'Closed Transactions'!C3=""),"",IF('Closed Transactions'!B3="","Sell","Buy")) -> Buy | AD6: ='Closed Transactions'!I3 -> 610000 | AE6: =IF('Closed Transactions'!J3="","",'Closed Transactions'!J3) -> 0.025 | AF6: =IF('Closed Transactions'!K3="","", 'Closed Transactions'!K3) -> 15250
B7: 45896 | C7: Zia Hassanzadeh | E7: 700000 | F7: 0.03 | G7: =E7*F7 -> 21000 | J7: 45975 | K7: Leonard Abreu | M7: 500000 | N7: 0.025 | O7: =N7*M7 -> 12500 | W7: =U7*V7 -> 0 | Z7: =IF('Closed Transactions'!A4="", "",'Closed Transactions'!A4) -> 45706 | AA7: =MONTH(Z7) -> 2 | AB7: =IF('Closed Transactions'!F4="","",'Closed Transactions'!F4) -> Cristina Samaha | AC7: =IF(AND('Closed Transactions'!B4="",'Closed Transactions'!C4=""),"",IF('Closed Transactions'!B4="","Sell","Buy")) -> Buy | AD7: ='Closed Transactions'!I4 -> 415900 | AE7: =IF('Closed Transactions'!J4="","",'Closed Transactions'!J4) -> 0.024044241 | AF7: =IF('Closed Transactions'!K4="","", 'Closed Transactions'!K4) -> 10000
B8: 45930 | C8: Kyria | E8: 250000 | F8: 0.0075 | G8: =E8*F8 -> 1875 | J8: 45994 | K8: Sarah & Sam Bellet | M8: 1250000 | N8: 0.03 | O8: =N8*M8 -> 37500 | W8: =U8*V8 -> 0 | Z8: =IF('Closed Transactions'!A5="", "",'Closed Transactions'!A5) -> 45717 | AA8: =MONTH(Z8) -> 3 | AB8: =IF('Closed Transactions'!F5="","",'Closed Transactions'!F5) -> Kim & Damon Sidur | AC8: =IF(AND('Closed Transactions'!B5="",'Closed Transactions'!C5=""),"",IF('Closed Transactions'!B5="","Sell","Buy")) -> Buy | AD8: ='Closed Transactions'!I5 -> 2650 | AE8: =IF('Closed Transactions'!J5="","",'Closed Transactions'!J5) -> 0.25 | AF8: =IF('Closed Transactions'!K5="","", 'Closed Transactions'!K5) -> 662.5
B9: 45933 | C9: Amelia Stansell | E9: 750000 | F9: 0.03 | G9: =E9*F9 -> 22500 | J9: 45995 | K9: Michael Passante | M9: 250000 | N9: 0.03 | O9: =N9*M9 -> 7500 | W9: =U9*V9 -> 0 | Z9: =IF('Closed Transactions'!A6="", "",'Closed Transactions'!A6) -> 45724 | AA9: =MONTH(Z9) -> 3 | AB9: =IF('Closed Transactions'!F6="","",'Closed Transactions'!F6) -> Anne Duffy, Elizabeth & Ariel | AC9: =IF(AND('Closed Transactions'!B6="",'Closed Transactions'!C6=""),"",IF('Closed Transactions'!B6="","Sell","Buy")) -> Buy | AD9: ='Closed Transactions'!I6 -> 2995 | AE9: =IF('Closed Transactions'!J6="","",'Closed Transactions'!J6) -> 1 | AF9: =IF('Closed Transactions'!K6="","", 'Closed Transactions'!K6) -> 2995
B10: 45933 | C10: Joe Catalano | E10: 500000 | F10: 0.03 | G10: =E10*F10 -> 15000 | J10: 46000 | K10: Robert Yates | M10: 350000 | N10: 0.03 | O10: =N10*M10 -> 10500 | W10: =U10*V10 -> 0 | Z10: =IF('Closed Transactions'!A7="", "",'Closed Transactions'!A7) -> 45757 | AA10: =MONTH(Z10) -> 4 | AB10: =IF('Closed Transactions'!F7="","",'Closed Transactions'!F7) -> Lindsey Jasper & Ben Fielder | AC10: =IF(AND('Closed Transactions'!B7="",'Closed Transactions'!C7=""),"",IF('Closed Transactions'!B7="","Sell","Buy")) -> Buy | AD10: ='Closed Transactions'!I7 -> 750000 | AE10: =IF('Closed Transactions'!J7="","",'Closed Transactions'!J7) -> 0.03 | AF10: =IF('Closed Transactions'!K7="","", 'Closed Transactions'!K7) -> 22500
B11: 45936 | C11: Tom Palmer | E11: 500000 | F11: 0.03 | G11: =E11*F11 -> 15000 | J11: 46000 | K11: Zubeda & Ashraf Kadri | M11: 550000 | N11: 0.03 | O11: =N11*M11 -> 16500 | T11: =MONTH(S11) -> 1 | W11: =U11*V11 -> 0 | Z11: =IF('Closed Transactions'!A8="", "",'Closed Transactions'!A8) -> 45758 | AA11: =MONTH(Z11) -> 4 | AB11: =IF('Closed Transactions'!F8="","",'Closed Transactions'!F8) -> Doug Church | AC11: =IF(AND('Closed Transactions'!B8="",'Closed Transactions'!C8=""),"",IF('Closed Transactions'!B8="","Sell","Buy")) -> Sell | AD11: ='Closed Transactions'!I8 -> 1300000 | AE11: =IF('Closed Transactions'!J8="","",'Closed Transactions'!J8) -> 0.03 | AF11: =IF('Closed Transactions'!K8="","", 'Closed Transactions'!K8) -> 39000
B12: 45952 | C12: Joe Garon - Richmond referral | E12: 600000 | F12: 0.0075 | G12: =E12*F12 -> 4500 | J12: 46001 | K12: Alec Hurley | M12: 800000 | N12: 0.025 | O12: =N12*M12 -> 20000 | T12: =MONTH(S12) -> 1 | W12: =U12*V12 -> 0 | Z12: =IF('Closed Transactions'!A9="", "",'Closed Transactions'!A9) -> 45828 | AA12: =MONTH(Z12) -> 6 | AB12: =IF('Closed Transactions'!F9="","",'Closed Transactions'!F9) -> Ashraf Kadri | AC12: =IF(AND('Closed Transactions'!B9="",'Closed Transactions'!C9=""),"",IF('Closed Transactions'!B9="","Sell","Buy")) -> Buy | AD12: ='Closed Transactions'!I9 -> 390000 | AE12: =IF('Closed Transactions'!J9="","",'Closed Transactions'!J9) -> 0.0075 | AF12: =IF('Closed Transactions'!K9="","", 'Closed Transactions'!K9) -> 2925
B13: 45957 | C13: Carolyn Chappell | E13: 650000 | F13: 0.03 | G13: =E13*F13 -> 19500 | J13: 46002 | K13: Jon Lindenberg - investment | M13: 650000 | N13: 0.03 | O13: =N13*M13 -> 19500 | T13: =MONTH(S13) -> 1 | W13: =U13*V13 -> 0 | Z13: =IF('Closed Transactions'!A10="", "",'Closed Transactions'!A10) -> 45838 | AA13: =MONTH(Z13) -> 6 | AB13: =IF('Closed Transactions'!F10="","",'Closed Transactions'!F10) -> Nathan Desnoyers | AC13: =IF(AND('Closed Transactions'!B10="",'Closed Transactions'!C10=""),"",IF('Closed Transactions'!B10="","Sell","Buy")) -> Sell | AD13: ='Closed Transactions'!I10 -> 365000 | AE13: =IF('Closed Transactions'!J10="","",'Closed Transactions'!J10) -> 0 | AF13: =IF('Closed Transactions'!K10="","", 'Closed Transactions'!K10) -> 0
B14: 45958 | C14: Ronald Joseph - Vorsa | E14: 1800000 | F14: 0.025 | G14: =E14*F14 -> 45000 | J14: 46004 | K14: James T Bonner III | M14: 500000 | N14: 0.0225 | O14: =N14*M14 -> 11250 | T14: =MONTH(S14) -> 1 | W14: =U14*V14 -> 0 | Z14: =IF('Closed Transactions'!A11="", "",'Closed Transactions'!A11) -> 45839 | AA14: =MONTH(Z14) -> 7 | AB14: =IF('Closed Transactions'!F11="","",'Closed Transactions'!F11) -> Saria Alshaikhalia | AC14: =IF(AND('Closed Transactions'!B11="",'Closed Transactions'!C11=""),"",IF('Closed Transactions'!B11="","Sell","Buy")) -> Buy | AD14: ='Closed Transactions'!I11 -> 2195 | AE14: =IF('Closed Transactions'!J11="","",'Closed Transactions'!J11) -> 0.25 | AF14: =IF('Closed Transactions'!K11="","", 'Closed Transactions'!K11) -> 548.75
B15: 45960 | C15: Kevin Governor | E15: 1100000 | F15: 0.03 | G15: =E15*F15 -> 33000 | J15: 46004 | K15: Jordan Northrup | M15: 400000 | N15: 0.02 | O15: =N15*M15 -> 8000 | T15: =MONTH(S15) -> 1 | W15: =U15*V15 -> 0 | Z15: =IF('Closed Transactions'!A12="", "",'Closed Transactions'!A12) -> 45839 | AA15: =MONTH(Z15) -> 7 | AB15: =IF('Closed Transactions'!F12="","",'Closed Transactions'!F12) -> Sneha Durgapal & Alex Hennessy | AC15: =IF(AND('Closed Transactions'!B12="",'Closed Transactions'!C12=""),"",IF('Closed Transactions'!B12="","Sell","Buy")) -> Buy | AD15: ='Closed Transactions'!I12 -> 3150 | AE15: =IF('Closed Transactions'!J12="","",'Closed Transactions'!J12) -> 0 | AF15: =IF('Closed Transactions'!K12="","", 'Closed Transactions'!K12) -> 0
B16: 45968 | C16: JR Spear | E16: 500000 | F16: 0.03 | G16: =E16*F16 -> 15000 | J16: 46005 | K16: Ramzi Samaha | M16: 600000 | N16: 0.03 | O16: =N16*M16 -> 18000 | T16: =MONTH(S16) -> 1 | W16: =U16*V16 -> 0 | Z16: =IF('Closed Transactions'!A13="", "",'Closed Transactions'!A13) -> 45845 | AA16: =MONTH(Z16) -> 7 | AB16: =IF('Closed Transactions'!F13="","",'Closed Transactions'!F13) -> Jared Traggic & Kiana Spearman | AC16: =IF(AND('Closed Transactions'!B13="",'Closed Transactions'!C13=""),"",IF('Closed Transactions'!B13="","Sell","Buy")) -> Buy | AD16: ='Closed Transactions'!I13 -> 2400 | AE16: =IF('Closed Transactions'!J13="","",'Closed Transactions'!J13) -> 0.25 | AF16: =IF('Closed Transactions'!K13="","", 'Closed Transactions'!K13) -> 600
B17: 45969 | C17: Melisa & Rob Banks | E17: 1700000 | F17: 0.03 | G17: =E17*F17 -> 51000 | J17: 46006 | K17: Miguel Shaban | M17: 750000 | N17: 0.03 | O17: =N17*M17 -> 22500 | T17: =MONTH(S17) -> 1 | W17: =U17*V17 -> 0 | Z17: =IF('Closed Transactions'!A14="", "",'Closed Transactions'!A14) -> 45853 | AA17: =MONTH(Z17) -> 7 | AB17: =IF('Closed Transactions'!F14="","",'Closed Transactions'!F14) -> Kristine & Ken Delos Reyes | AC17: =IF(AND('Closed Transactions'!B14="",'Closed Transactions'!C14=""),"",IF('Closed Transactions'!B14="","Sell","Buy")) -> Buy | AD17: ='Closed Transactions'!I14 -> 665280 | AE17: =IF('Closed Transactions'!J14="","",'Closed Transactions'!J14) -> 0.00901876 | AF17: =IF('Closed Transactions'!K14="","", 'Closed Transactions'!K14) -> 6000.0007
B18: 45992 | C18: Liam Mulcahy | E18: 850000 | F18: 0.03 | G18: =E18*F18 -> 25500 | J18: 46003 | K18: Jon Jeyachandran | M18: 400000 | N18: 0.03 | O18: =N18*M18 -> 12000 | T18: =MONTH(S18) -> 1 | W18: =U18*V18 -> 0 | Z18: =IF('Closed Transactions'!A15="", "",'Closed Transactions'!A15) -> 45884 | AA18: =MONTH(Z18) -> 8 | AB18: =IF('Closed Transactions'!F15="","",'Closed Transactions'!F15) -> Anne Duffy, Joshua Foote, Kate McCusker | AC18: =IF(AND('Closed Transactions'!B15="",'Closed Transactions'!C15=""),"",IF('Closed Transactions'!B15="","Sell","Buy")) -> Buy | AD18: ='Closed Transactions'!I15 -> 3295 | AE18: =IF('Closed Transactions'!J15="","",'Closed Transactions'!J15) -> 1 | AF18: =IF('Closed Transactions'!K15="","", 'Closed Transactions'!K15) -> 3295
B19: 45993 | C19: Norberto Daluz | E19: 1400000 | F19: 0.03 | G19: =E19*F19 -> 42000 | J19: 46006 | K19: Dave Eluma | M19: 650000 | N19: 0.03 | O19: =N19*M19 -> 19500 | T19: =MONTH(S19) -> 1 | W19: =U19*V19 -> 0 | Z19: =IF('Closed Transactions'!A16="", "",'Closed Transactions'!A16) -> 45903 | AA19: =MONTH(Z19) -> 9 | AB19: =IF('Closed Transactions'!F16="","",'Closed Transactions'!F16) -> Cintia Samaha Desnoyers | AC19: =IF(AND('Closed Transactions'!B16="",'Closed Transactions'!C16=""),"",IF('Closed Transactions'!B16="","Sell","Buy")) -> Buy | AD19: ='Closed Transactions'!I16 -> 615000 | AE19: =IF('Closed Transactions'!J16="","",'Closed Transactions'!J16) -> 0 | AF19: =IF('Closed Transactions'!K16="","", 'Closed Transactions'!K16) -> 0
B20: 45994 | C20: Rachel McQuillen | E20: 600000 | F20: 0.03 | G20: =E20*F20 -> 18000 | O20: =N20*M20 -> 0 | T20: =MONTH(S20) -> 1 | W20: =U20*V20 -> 0 | Z20: =IF('Closed Transactions'!A17="", "",'Closed Transactions'!A17) -> 45910 | AA20: =MONTH(Z20) -> 9 | AB20: =IF('Closed Transactions'!F17="","",'Closed Transactions'!F17) -> Ashleigh Verma & Tapinder Garcha | AC20: =IF(AND('Closed Transactions'!B17="",'Closed Transactions'!C17=""),"",IF('Closed Transactions'!B17="","Sell","Buy")) -> Sell | AD20: ='Closed Transactions'!I17 -> 770000 | AE20: =IF('Closed Transactions'!J17="","",'Closed Transactions'!J17) -> 0.02 | AF20: =IF('Closed Transactions'!K17="","", 'Closed Transactions'!K17) -> 15400
B21: 45995 | C21: Allen Liu | E21: 750000 | F21: 0.03 | G21: =E21*F21 -> 22500 | O21: =N21*M21 -> 0 | T21: =MONTH(S21) -> 1 | W21: =U21*V21 -> 0 | Z21: =IF('Closed Transactions'!A18="", "",'Closed Transactions'!A18) -> 45920 | AA21: =MONTH(Z21) -> 9 | AB21: =IF('Closed Transactions'!F18="","",'Closed Transactions'!F18) -> Cintia Samaha Desnoyers | AC21: =IF(AND('Closed Transactions'!B18="",'Closed Transactions'!C18=""),"",IF('Closed Transactions'!B18="","Sell","Buy")) -> Sell | AD21: ='Closed Transactions'!I18 -> 2400 | AE21: =IF('Closed Transactions'!J18="","",'Closed Transactions'!J18) -> 0 | AF21: =IF('Closed Transactions'!K18="","", 'Closed Transactions'!K18) -> 0
B22: 45995 | C22: Nick Minanago | E22: 750000 | F22: 0.03 | G22: =E22*F22 -> 22500 | O22: =N22*M22 -> 0 | T22: =MONTH(S22) -> 1 | W22: =U22*V22 -> 0 | Z22: =IF('Closed Transactions'!A19="", "",'Closed Transactions'!A19) -> 45981 | AA22: =MONTH(Z22) -> 11 | AB22: =IF('Closed Transactions'!F19="","",'Closed Transactions'!F19) -> Noel Contreras | AC22: =IF(AND('Closed Transactions'!B19="",'Closed Transactions'!C19=""),"",IF('Closed Transactions'!B19="","Sell","Buy")) -> Sell | AD22: ='Closed Transactions'!I19 -> 1500 | AE22: =IF('Closed Transactions'!J19="","",'Closed Transactions'!J19) -> 0 | AF22: =IF('Closed Transactions'!K19="","", 'Closed Transactions'!K19) -> 0
B23: 45995 | C23: Cheryl Zellmer | E23: 350000 | F23: 0.03 | G23: =E23*F23 -> 10500 | O23: =N23*M23 -> 0 | T23: =MONTH(S23) -> 1 | W23: =U23*V23 -> 0 | Z23: =IF('Closed Transactions'!A20="", "",'Closed Transactions'!A20) | AA23: =MONTH(Z23) -> #VALUE! | AB23: =IF('Closed Transactions'!F20="","",'Closed Transactions'!F20) | AC23: =IF(AND('Closed Transactions'!B20="",'Closed Transactions'!C20=""),"",IF('Closed Transactions'!B20="","Sell","Buy")) | AD23: ='Closed Transactions'!I20 -> 0 | AE23: =IF('Closed Transactions'!J20="","",'Closed Transactions'!J20) | AF23: =IF('Closed Transactions'!K20="","", 'Closed Transactions'!K20)
B24: 45995 | C24: Jay Chikobe | E24: 550000 | F24: 0.03 | G24: =E24*F24 -> 16500 | O24: =N24*M24 -> 0 | T24: =MONTH(S24) -> 1 | W24: =U24*V24 -> 0 | Z24: =IF('Closed Transactions'!A21="", "",'Closed Transactions'!A21) | AA24: =MONTH(Z24) -> #VALUE! | AB24: =IF('Closed Transactions'!F21="","",'Closed Transactions'!F21) | AC24: =IF(AND('Closed Transactions'!B21="",'Closed Transactions'!C21=""),"",IF('Closed Transactions'!B21="","Sell","Buy")) | AD24: ='Closed Transactions'!I21 -> 0 | AE24: =IF('Closed Transactions'!J21="","",'Closed Transactions'!J21) | AF24: =IF('Closed Transactions'!K21="","", 'Closed Transactions'!K21)
B25: 45995 | C25: Julia Taylor | E25: 550000 | F25: 0.03 | G25: =E25*F25 -> 16500 | O25: =N25*M25 -> 0 | T25: =MONTH(S25) -> 1 | W25: =U25*V25 -> 0 | Z25: =IF('Closed Transactions'!A22="", "",'Closed Transactions'!A22) | AA25: =MONTH(Z25) -> #VALUE! | AB25: =IF('Closed Transactions'!F22="","",'Closed Transactions'!F22) | AC25: =IF(AND('Closed Transactions'!B22="",'Closed Transactions'!C22=""),"",IF('Closed Transactions'!B22="","Sell","Buy")) | AD25: ='Closed Transactions'!I22 -> 0 | AE25: =IF('Closed Transactions'!J22="","",'Closed Transactions'!J22) | AF25: =IF('Closed Transactions'!K22="","", 'Closed Transactions'!K22)
B26: 45995 | C26: Raja Bala | E26: 550000 | F26: 0.03 | G26: =E26*F26 -> 16500 | O26: =N26*M26 -> 0 | T26: =MONTH(S26) -> 1 | W26: =U26*V26 -> 0 | Z26: =IF('Closed Transactions'!A23="", "",'Closed Transactions'!A23) | AA26: =MONTH(Z26) -> #VALUE! | AB26: =IF('Closed Transactions'!F23="","",'Closed Transactions'!F23) | AC26: =IF(AND('Closed Transactions'!B23="",'Closed Transactions'!C23=""),"",IF('Closed Transactions'!B23="","Sell","Buy")) | AD26: ='Closed Transactions'!I23 -> 0 | AE26: =IF('Closed Transactions'!J23="","",'Closed Transactions'!J23) | AF26: =IF('Closed Transactions'!K23="","", 'Closed Transactions'!K23)
B27: 45995 | C27: Cris Gains | E27: 500000 | F27: 0.03 | G27: =E27*F27 -> 15000 | O27: =N27*M27 -> 0 | T27: =MONTH(S27) -> 1 | W27: =U27*V27 -> 0 | Z27: =IF('Closed Transactions'!A24="", "",'Closed Transactions'!A24) | AA27: =MONTH(Z27) -> #VALUE! | AB27: =IF('Closed Transactions'!F24="","",'Closed Transactions'!F24) | AC27: =IF(AND('Closed Transactions'!B24="",'Closed Transactions'!C24=""),"",IF('Closed Transactions'!B24="","Sell","Buy")) | AD27: ='Closed Transactions'!I24 -> 0 | AE27: =IF('Closed Transactions'!J24="","",'Closed Transactions'!J24) | AF27: =IF('Closed Transactions'!K24="","", 'Closed Transactions'!K24)
B28: 45995 | C28: Samantha Jennings | E28: 750000 | F28: 0.03 | G28: =E28*F28 -> 22500 | O28: =N28*M28 -> 0 | T28: =MONTH(S28) -> 1 | W28: =U28*V28 -> 0 | Z28: =IF('Closed Transactions'!A25="", "",'Closed Transactions'!A25) | AA28: =MONTH(Z28) -> #VALUE! | AB28: =IF('Closed Transactions'!F25="","",'Closed Transactions'!F25) | AC28: =IF(AND('Closed Transactions'!B25="",'Closed Transactions'!C25=""),"",IF('Closed Transactions'!B25="","Sell","Buy")) | AD28: ='Closed Transactions'!I25 -> 0 | AE28: =IF('Closed Transactions'!J25="","",'Closed Transactions'!J25) | AF28: =IF('Closed Transactions'!K25="","", 'Closed Transactions'!K25)
B29: 45995 | C29: The Miravis | E29: 750000 | F29: 0.03 | G29: =E29*F29 -> 22500 | O29: =N29*M29 -> 0 | T29: =MONTH(S29) -> 1 | W29: =U29*V29 -> 0 | Z29: =IF('Closed Transactions'!A26="", "",'Closed Transactions'!A26) | AA29: =MONTH(Z29) -> #VALUE! | AB29: =IF('Closed Transactions'!F26="","",'Closed Transactions'!F26) | AC29: =IF(AND('Closed Transactions'!B26="",'Closed Transactions'!C26=""),"",IF('Closed Transactions'!B26="","Sell","Buy")) | AD29: ='Closed Transactions'!I26 -> 0 | AE29: =IF('Closed Transactions'!J26="","",'Closed Transactions'!J26) | AF29: =IF('Closed Transactions'!K26="","", 'Closed Transactions'!K26)
B30: 45996 | C30: Henry Asherbranner | E30: 550000 | F30: 0.03 | G30: =E30*F30 -> 16500 | O30: =N30*M30 -> 0 | T30: =MONTH(S30) -> 1 | W30: =U30*V30 -> 0 | Z30: =IF('Closed Transactions'!A27="", "",'Closed Transactions'!A27) | AA30: =MONTH(Z30) -> #VALUE! | AB30: =IF('Closed Transactions'!F27="","",'Closed Transactions'!F27) | AC30: =IF(AND('Closed Transactions'!B27="",'Closed Transactions'!C27=""),"",IF('Closed Transactions'!B27="","Sell","Buy")) | AD30: ='Closed Transactions'!I27 -> 0 | AE30: =IF('Closed Transactions'!J27="","",'Closed Transactions'!J27) | AF30: =IF('Closed Transactions'!K27="","", 'Closed Transactions'!K27)
B31: 45996 | C31: Ben Martin | E31: 450000 | F31: 0.0075 | G31: =E31*F31 -> 3375 | O31: =N31*M31 -> 0 | T31: =MONTH(S31) -> 1 | W31: =U31*V31 -> 0 | Z31: =IF('Closed Transactions'!A28="", "",'Closed Transactions'!A28) | AA31: =MONTH(Z31) -> #VALUE! | AB31: =IF('Closed Transactions'!F28="","",'Closed Transactions'!F28) | AC31: =IF(AND('Closed Transactions'!B28="",'Closed Transactions'!C28=""),"",IF('Closed Transactions'!B28="","Sell","Buy")) | AD31: ='Closed Transactions'!I28 -> 0 | AE31: =IF('Closed Transactions'!J28="","",'Closed Transactions'!J28) | AF31: =IF('Closed Transactions'!K28="","", 'Closed Transactions'!K28)
... B34: 45999 | C34: Austin Kennedy | E34: 750000 | F34: 0.03 | G34: =E34*F34 -> 22500 | O34: =N34*M34 -> 0 | T34: =MONTH(S34) -> 1 | W34: =U34*V34 -> 0 | Z34: =IF('Closed Transactions'!A31="", "",'Closed Transactions'!A31) | AA34: =MONTH(Z34) -> #VALUE! | AB34: =IF('Closed Transactions'!F31="","",'Closed Transactions'!F31) | AC34: =IF(AND('Closed Transactions'!B31="",'Closed Transactions'!C31=""),"",IF('Closed Transactions'!B31="","Sell","Buy")) | AD34: ='Closed Transactions'!I31 -> 0 | AE34: =IF('Closed Transactions'!J31="","",'Closed Transactions'!J31) | AF34: =IF('Closed Transactions'!K31="","", 'Closed Transactions'!K31)
B35: 46000 | C35: Victor Rhoder | E35: 1200000 | F35: 0.03 | G35: =E35*F35 -> 36000 | O35: =N35*M35 -> 0 | Q35: Total Under Contract | W35: =SUM(W6:W34) -> 0 | Z35: =IF('Closed Transactions'!A32="", "",'Closed Transactions'!A32) | AA35: =MONTH(Z35) -> #VALUE! | AB35: =IF('Closed Transactions'!F32="","",'Closed Transactions'!F32) | AC35: =IF(AND('Closed Transactions'!B32="",'Closed Transactions'!C32=""),"",IF('Closed Transactions'!B32="","Sell","Buy")) | AD35: ='Closed Transactions'!I32 -> 0 | AE35: =IF('Closed Transactions'!J32="","",'Closed Transactions'!J32) | AF35: =IF('Closed Transactions'!K32="","", 'Closed Transactions'!K32)
B36: 46000 | C36: Quinton - Richmond referral | E36: 500000 | F36: 0.0075 | G36: =E36*F36 -> 3750 | I36: "Hot" and Confused Prospects | Q36: Signed Listing Agreements | Z36: =IF('Closed Transactions'!A33="", "",'Closed Transactions'!A33) | AA36: =MONTH(Z36) -> #VALUE! | AB36: =IF('Closed Transactions'!F33="","",'Closed Transactions'!F33) | AC36: =IF(AND('Closed Transactions'!B33="",'Closed Transactions'!C33=""),"",IF('Closed Transactions'!B33="","Sell","Buy")) | AD36: ='Closed Transactions'!I33 -> 0 | AE36: =IF('Closed Transactions'!J33="","",'Closed Transactions'!J33) | AF36: =IF('Closed Transactions'!K33="","", 'Closed Transactions'!K33)
B37: 46000 | C37: Roland | E37: 400000 | F37: 0.03 | G37: =E37*F37 -> 12000 | Z37: =IF('Closed Transactions'!A34="", "",'Closed Transactions'!A34) | AA37: =MONTH(Z37) -> #VALUE! | AB37: =IF('Closed Transactions'!F34="","",'Closed Transactions'!F34) | AC37: =IF(AND('Closed Transactions'!B34="",'Closed Transactions'!C34=""),"",IF('Closed Transactions'!B34="","Sell","Buy")) | AD37: ='Closed Transactions'!I34 -> 0 | AE37: =IF('Closed Transactions'!J34="","",'Closed Transactions'!J34) | AF37: =IF('Closed Transactions'!K34="","", 'Closed Transactions'!K34)
B38: 46000 | C38: Johnny Sower | E38: 650000 | F38: 0.03 | G38: =E38*F38 -> 19500 | J38: Date | K38: Client Name | L38: P/P Rating | M38: Est. Sales Price | N38: % | O38: Potential GCI | Q38: Client Name | R38: Notes: Buy/Sell, signed agreements, status, updates | S38: Closing date | T38: For PIE Summary | U38: Sales Price | V38: % | W38: Estimated GCI | Z38: =IF('Closed Transactions'!A35="", "",'Closed Transactions'!A35) | AA38: =MONTH(Z38) -> #VALUE! | AB38: =IF('Closed Transactions'!F35="","",'Closed Transactions'!F35) | AC38: =IF(AND('Closed Transactions'!B35="",'Closed Transactions'!C35=""),"",IF('Closed Transactions'!B35="","Sell","Buy")) | AD38: ='Closed Transactions'!I35 -> 0 | AE38: =IF('Closed Transactions'!J35="","",'Closed Transactions'!J35) | AF38: =IF('Closed Transactions'!K35="","", 'Closed Transactions'!K35)
B39: 46001 | C39: John McGeehan | E39: 350000 | F39: 0.03 | G39: =E39*F39 -> 10500 | J39: 46001 | K39: Lucy Pearl | M39: 700000 | N39: 0.03 | O39: =N39*M39 -> 21000 | T39: =MONTH(S39) -> 1 | W39: =U39*V39 -> 0 | Z39: =IF('Closed Transactions'!A36="", "",'Closed Transactions'!A36) | AA39: =MONTH(Z39) -> #VALUE! | AB39: =IF('Closed Transactions'!F36="","",'Closed Transactions'!F36) | AC39: =IF(AND('Closed Transactions'!B36="",'Closed Transactions'!C36=""),"",IF('Closed Transactions'!B36="","Sell","Buy")) | AD39: ='Closed Transactions'!I36 -> 0 | AE39: =IF('Closed Transactions'!J36="","",'Closed Transactions'!J36) | AF39: =IF('Closed Transactions'!K36="","", 'Closed Transactions'!K36)
B40: 46001 | C40: Linh Huynh | E40: 600000 | F40: 0.03 | G40: =E40*F40 -> 18000 | O40: =N40*M40 -> 0 | T40: =MONTH(S40) -> 1 | W40: =U40*V40 -> 0 | Z40: =IF('Closed Transactions'!A37="", "",'Closed Transactions'!A37) | AA40: =MONTH(Z40) -> #VALUE! | AB40: =IF('Closed Transactions'!F37="","",'Closed Transactions'!F37) | AC40: =IF(AND('Closed Transactions'!B37="",'Closed Transactions'!C37=""),"",IF('Closed Transactions'!B37="","Sell","Buy")) | AD40: ='Closed Transactions'!I37 -> 0 | AE40: =IF('Closed Transactions'!J37="","",'Closed Transactions'!J37) | AF40: =IF('Closed Transactions'!K37="","", 'Closed Transactions'!K37)
B41: 46001 | C41: Art Hamerschlag | E41: 1600000 | F41: 0.03 | G41: =E41*F41 -> 48000 | O41: =N41*M41 -> 0 | T41: =MONTH(S41) -> 1 | W41: =U41*V41 -> 0 | Z41: =IF('Closed Transactions'!A38="", "",'Closed Transactions'!A38) | AA41: =MONTH(Z41) -> #VALUE! | AB41: =IF('Closed Transactions'!F38="","",'Closed Transactions'!F38) | AC41: =IF(AND('Closed Transactions'!B38="",'Closed Transactions'!C38=""),"",IF('Closed Transactions'!B38="","Sell","Buy")) | AD41: ='Closed Transactions'!I38 -> 0 | AE41: =IF('Closed Transactions'!J38="","",'Closed Transactions'!J38) | AF41: =IF('Closed Transactions'!K38="","", 'Closed Transactions'!K38)
B42: 46001 | C42: Victor Kremer | E42: 500000 | F42: 0.03 | G42: =E42*F42 -> 15000 | O42: =N42*M42 -> 0 | T42: =MONTH(S42) -> 1 | W42: =U42*V42 -> 0 | Z42: =IF('Closed Transactions'!A39="", "",'Closed Transactions'!A39) | AA42: =MONTH(Z42) -> #VALUE! | AB42: =IF('Closed Transactions'!F39="","",'Closed Transactions'!F39) | AC42: =IF(AND('Closed Transactions'!B39="",'Closed Transactions'!C39=""),"",IF('Closed Transactions'!B39="","Sell","Buy")) | AD42: ='Closed Transactions'!I39 -> 0 | AE42: =IF('Closed Transactions'!J39="","",'Closed Transactions'!J39) | AF42: =IF('Closed Transactions'!K39="","", 'Closed Transactions'!K39)
...

Sheet Closed Transactions
A1: A transaction has closed! Enter closing details in tan cells.
A2: COE | B2: Buy | C2: Sell | D2: Source | E2: Referral Past Client | F2: Client Name | G2: Prop Address | H2: LP | I2: SP | J2: Comm % | K2: Gross Commission | L2: Enter Referral Fee in $ | M2: Agent Net Income (Minus Franchise, Marketing, Office, Referral) | N2: Brokerage Income (Franchise, Marketing, Office) | P2: SP | Q2: Jan | S2: Feb | U2: Mar | W2: Apr | Y2: May | AA2: Jun | AC2: Jul | AE2: Aug | AG2: Sep | AI2: Oct | AK2: Nov | AM2: Dec
A3: 45667 | B3: 1 | D3: BNI | F3: Kevin Zhao | G3: 6516 Medinah Ln, Alexandrria, 33132 | H3: 590000 | I3: 610000 | J3: 0.025 | K3: =IF(ISBLANK(A3),"",(I3*J3)) -> 15250 | L3: 0 | M3: =IF((ISBLANK(A3)),"",'Fee calc_closed Transactions'!F3) -> 10370 | N3: =IF(K3="","",'Fee calc_closed Transactions'!G3) -> 4880 | P3: =IF(ISBLANK(A3),"0",I3) -> 610000 | Q3: =IF(MONTH(A3)=1,IF((ISBLANK(B3)),0,(M3)),"0") -> 10370 | R3: =IF(MONTH(A3)=1,IF((ISBLANK(C3)),0,(M3)),"0") -> 0 | S3: =IF(MONTH(A3)=2,IF((ISBLANK(B3)),0,(M3)),"0") -> 0 | T3: =IF(MONTH(A3)=2,IF((ISBLANK(C3)),0,(M3)),"0") -> 0 | U3: =IF(MONTH(A3)=3,IF((ISBLANK(B3)),0,(M3)),"0") -> 0 | V3: =IF(MONTH(A3)=3,IF((ISBLANK(C3)),0,(M3)),"0") -> 0 | W3: =IF(MONTH(A3)=4,IF((ISBLANK(B3)),0,(M3)),"0") -> 0 | X3: =IF(MONTH(A3)=4,IF((ISBLANK(C3)),0,(M3)),"0") -> 0 | Y3: =IF(MONTH(A3)=5,IF((ISBLANK(B3)),0,(M3)),"0") -> 0 | Z3: =IF(MONTH(A3)=5,IF((ISBLANK(C3)),0,(M3)),"0") -> 0 | AA3: =IF(MONTH(A3)=6,IF((ISBLANK(B3)),0,(M3)),"0") -> 0 | AB3: =IF(MONTH(A3)=6,IF((ISBLANK(C3)),0,(M3)),"0") -> 0 | AC3: =IF(MONTH(A3)=7,IF((ISBLANK(B3)),0,(M3)),"0") -> 0 | AD3: =IF(MONTH(A3)=7,IF((ISBLANK(C3)),0,(M3)),"0") -> 0 | AE3: =IF(MONTH(A3)=8,IF((ISBLANK(B3)),0,(M3)),"0") -> 0 | AF3: =IF(MONTH(A3)=8,IF((ISBLANK(C3)),0,(M3)),"0") -> 0 | AG3: =IF(MONTH(A3)=9,IF((ISBLANK(B3)),0,(M3)),"0") -> 0 | AH3: =IF(MONTH(A3)=9,IF((ISBLANK(C3)),0,(M3)),"0") -> 0 | AI3: =IF(MONTH(A3)=10,IF((ISBLANK(B3)),0,(M3)),"0") -> 0 | AJ3: =IF(MONTH(A3)=10,IF((ISBLANK(C3)),0,(M3)),"0") -> 0 | AK3: =IF(MONTH(A3)=11,IF((ISBLANK(B3)),0,(M3)),"0") -> 0 | AL3: =IF(MONTH(A3)=11,IF((ISBLANK(C3)),0,(M3)),"0") -> 0 | AM3: =IF(MONTH(A3)=12,IF((ISBLANK(B3)),0,(M3)),"0") -> 0 | AN3: =IF(MONTH(A3)=12,IF((ISBLANK(C3)),0,(M3)),"0") -> 0
A4: 45706 | B4: 1 | D4: SOI | F4: Cristina Samaha | G4: 3452 Belleplain Ct, Dumfries | H4: 415900 | I4: 415900 | J4: 0.024044241 | K4: =IF(ISBLANK(A4),"",(I4*J4)) -> 10000 | L4: 0 | M4: =IF((ISBLANK(A4)),"",'Fee calc_closed Transactions'!F4) -> 6880 | N4: =IF(K4="","",'Fee calc_closed Transactions'!G4) -> 3120 | P4: =IF(ISBLANK(A4),"0",I4) -> 415900 | Q4: =IF(MONTH(A4)=1,IF((ISBLANK(B4)),0,(M4)),"0") -> 0 | R4: =IF(MONTH(A4)=1,IF((ISBLANK(C4)),0,(M4)),"0") -> 0 | S4: =IF(MONTH(A4)=2,IF((ISBLANK(B4)),0,(M4)),"0") -> 6880 | T4: =IF(MONTH(A4)=2,IF((ISBLANK(C4)),0,(M4)),"0") -> 0 | U4: =IF(MONTH(A4)=3,IF((ISBLANK(B4)),0,(M4)),"0") -> 0 | V4: =IF(MONTH(A4)=3,IF((ISBLANK(C4)),0,(M4)),"0") -> 0 | W4: =IF(MONTH(A4)=4,IF((ISBLANK(B4)),0,(M4)),"0") -> 0 | X4: =IF(MONTH(A4)=4,IF((ISBLANK(C4)),0,(M4)),"0") -> 0 | Y4: =IF(MONTH(A4)=5,IF((ISBLANK(B4)),0,(M4)),"0") -> 0 | Z4: =IF(MONTH(A4)=5,IF((ISBLANK(C4)),0,(M4)),"0") -> 0 | AA4: =IF(MONTH(A4)=6,IF((ISBLANK(B4)),0,(M4)),"0") -> 0 | AB4: =IF(MONTH(A4)=6,IF((ISBLANK(C4)),0,(M4)),"0") -> 0 | AC4: =IF(MONTH(A4)=7,IF((ISBLANK(B4)),0,(M4)),"0") -> 0 | AD4: =IF(MONTH(A4)=7,IF((ISBLANK(C4)),0,(M4)),"0") -> 0 | AE4: =IF(MONTH(A4)=8,IF((ISBLANK(B4)),0,(M4)),"0") -> 0 | AF4: =IF(MONTH(A4)=8,IF((ISBLANK(C4)),0,(M4)),"0") -> 0 | AG4: =IF(MONTH(A4)=9,IF((ISBLANK(B4)),0,(M4)),"0") -> 0 | AH4: =IF(MONTH(A4)=9,IF((ISBLANK(C4)),0,(M4)),"0") -> 0 | AI4: =IF(MONTH(A4)=10,IF((ISBLANK(B4)),0,(M4)),"0") -> 0 | AJ4: =IF(MONTH(A4)=10,IF((ISBLANK(C4)),0,(M4)),"0") -> 0 | AK4: =IF(MONTH(A4)=11,IF((ISBLANK(B4)),0,(M4)),"0") -> 0 | AL4: =IF(MONTH(A4)=11,IF((ISBLANK(C4)),0,(M4)),"0") -> 0 | AM4: =IF(MONTH(A4)=12,IF((ISBLANK(B4)),0,(M4)),"0") -> 0 | AN4: =IF(MONTH(A4)=12,IF((ISBLANK(C4)),0,(M4)),"0") -> 0
A5: 45717 | B5: 1 | D5: Sign Call | F5: Kim & Damon Sidur | G5: 3382 Gunston Rd, Alexandria | H5: 2600 | I5: 2650 | J5: 0.25 | K5: =IF(ISBLANK(A5),"",(I5*J5)) -> 662.5 | L5: 0 | M5: =IF((ISBLANK(A5)),"",'Fee calc_closed Transactions'!F5) -> 563.125 | N5: =IF(K5="","",'Fee calc_closed Transactions'!G5) -> 99.375 | P5: =IF(ISBLANK(A5),"0",I5) -> 2650 | Q5: =IF(MONTH(A5)=1,IF((ISBLANK(B5)),0,(M5)),"0") -> 0 | R5: =IF(MONTH(A5)=1,IF((ISBLANK(C5)),0,(M5)),"0") -> 0 | S5: =IF(MONTH(A5)=2,IF((ISBLANK(B5)),0,(M5)),"0") -> 0 | T5: =IF(MONTH(A5)=2,IF((ISBLANK(C5)),0,(M5)),"0") -> 0 | U5: =IF(MONTH(A5)=3,IF((ISBLANK(B5)),0,(M5)),"0") -> 563.125 | V5: =IF(MONTH(A5)=3,IF((ISBLANK(C5)),0,(M5)),"0") -> 0 | W5: =IF(MONTH(A5)=4,IF((ISBLANK(B5)),0,(M5)),"0") -> 0 | X5: =IF(MONTH(A5)=4,IF((ISBLANK(C5)),0,(M5)),"0") -> 0 | Y5: =IF(MONTH(A5)=5,IF((ISBLANK(B5)),0,(M5)),"0") -> 0 | Z5: =IF(MONTH(A5)=5,IF((ISBLANK(C5)),0,(M5)),"0") -> 0 | AA5: =IF(MONTH(A5)=6,IF((ISBLANK(B5)),0,(M5)),"0") -> 0 | AB5: =IF(MONTH(A5)=6,IF((ISBLANK(C5)),0,(M5)),"0") -> 0 | AC5: =IF(MONTH(A5)=7,IF((ISBLANK(B5)),0,(M5)),"0") -> 0 | AD5: =IF(MONTH(A5)=7,IF((ISBLANK(C5)),0,(M5)),"0") -> 0 | AE5: =IF(MONTH(A5)=8,IF((ISBLANK(B5)),0,(M5)),"0") -> 0 | AF5: =IF(MONTH(A5)=8,IF((ISBLANK(C5)),0,(M5)),"0") -> 0 | AG5: =IF(MONTH(A5)=9,IF((ISBLANK(B5)),0,(M5)),"0") -> 0 | AH5: =IF(MONTH(A5)=9,IF((ISBLANK(C5)),0,(M5)),"0") -> 0 | AI5: =IF(MONTH(A5)=10,IF((ISBLANK(B5)),0,(M5)),"0") -> 0 | AJ5: =IF(MONTH(A5)=10,IF((ISBLANK(C5)),0,(M5)),"0") -> 0 | AK5: =IF(MONTH(A5)=11,IF((ISBLANK(B5)),0,(M5)),"0") -> 0 | AL5: =IF(MONTH(A5)=11,IF((ISBLANK(C5)),0,(M5)),"0") -> 0 | AM5: =IF(MONTH(A5)=12,IF((ISBLANK(B5)),0,(M5)),"0") -> 0 | AN5: =IF(MONTH(A5)=12,IF((ISBLANK(C5)),0,(M5)),"0") -> 0
A6: 45724 | B6: 1 | C6: 1 | D6: realtor referral | F6: Anne Duffy, Elizabeth & Ariel | G6: 926 N Edgewood St #1, Arlington | H6: 2995 | I6: 2995 | J6: 1 | K6: =IF(ISBLANK(A6),"",(I6*J6)) -> 2995 | L6: 749 | M6: =IF((ISBLANK(A6)),"",'Fee calc_closed Transactions'!F6) -> 1909.1 | N6: =IF(K6="","",'Fee calc_closed Transactions'!G6) -> 336.9 | P6: =IF(ISBLANK(A6),"0",I6) -> 2995 | Q6: =IF(MONTH(A6)=1,IF((ISBLANK(B6)),0,(M6)),"0") -> 0 | R6: =IF(MONTH(A6)=1,IF((ISBLANK(C6)),0,(M6)),"0") -> 0 | S6: =IF(MONTH(A6)=2,IF((ISBLANK(B6)),0,(M6)),"0") -> 0 | T6: =IF(MONTH(A6)=2,IF((ISBLANK(C6)),0,(M6)),"0") -> 0 | U6: =IF(MONTH(A6)=3,IF((ISBLANK(B6)),0,(M6)),"0") -> 1909.1 | V6: =IF(MONTH(A6)=3,IF((ISBLANK(C6)),0,(M6)),"0") -> 1909.1 | W6: =IF(MONTH(A6)=4,IF((ISBLANK(B6)),0,(M6)),"0") -> 0 | X6: =IF(MONTH(A6)=4,IF((ISBLANK(C6)),0,(M6)),"0") -> 0 | Y6: =IF(MONTH(A6)=5,IF((ISBLANK(B6)),0,(M6)),"0") -> 0 | Z6: =IF(MONTH(A6)=5,IF((ISBLANK(C6)),0,(M6)),"0") -> 0 | AA6: =IF(MONTH(A6)=6,IF((ISBLANK(B6)),0,(M6)),"0") -> 0 | AB6: =IF(MONTH(A6)=6,IF((ISBLANK(C6)),0,(M6)),"0") -> 0 | AC6: =IF(MONTH(A6)=7,IF((ISBLANK(B6)),0,(M6)),"0") -> 0 | AD6: =IF(MONTH(A6)=7,IF((ISBLANK(C6)),0,(M6)),"0") -> 0 | AE6: =IF(MONTH(A6)=8,IF((ISBLANK(B6)),0,(M6)),"0") -> 0 | AF6: =IF(MONTH(A6)=8,IF((ISBLANK(C6)),0,(M6)),"0") -> 0 | AG6: =IF(MONTH(A6)=9,IF((ISBLANK(B6)),0,(M6)),"0") -> 0 | AH6: =IF(MONTH(A6)=9,IF((ISBLANK(C6)),0,(M6)),"0") -> 0 | AI6: =IF(MONTH(A6)=10,IF((ISBLANK(B6)),0,(M6)),"0") -> 0 | AJ6: =IF(MONTH(A6)=10,IF((ISBLANK(C6)),0,(M6)),"0") -> 0 | AK6: =IF(MONTH(A6)=11,IF((ISBLANK(B6)),0,(M6)),"0") -> 0 | AL6: =IF(MONTH(A6)=11,IF((ISBLANK(C6)),0,(M6)),"0") -> 0 | AM6: =IF(MONTH(A6)=12,IF((ISBLANK(B6)),0,(M6)),"0") -> 0 | AN6: =IF(MONTH(A6)=12,IF((ISBLANK(C6)),0,(M6)),"0") -> 0
A7: 45757 | B7: 1 | D7: referral | E7: Audra & Alex Macie | F7: Lindsey Jasper & Ben Fielder | G7: 1103 Criton St, Herndon, VA 20170 | H7: 750000 | I7: 750000 | J7: 0.03 | K7: =IF(ISBLANK(A7),"",(I7*J7)) -> 22500 | M7: =IF((ISBLANK(A7)),"",'Fee calc_closed Transactions'!F7) -> 19125 | N7: =IF(K7="","",'Fee calc_closed Transactions'!G7) -> 3375 | P7: =IF(ISBLANK(A7),"0",I7) -> 750000 | Q7: =IF(MONTH(A7)=1,IF((ISBLANK(B7)),0,(M7)),"0") -> 0 | R7: =IF(MONTH(A7)=1,IF((ISBLANK(C7)),0,(M7)),"0") -> 0 | S7: =IF(MONTH(A7)=2,IF((ISBLANK(B7)),0,(M7)),"0") -> 0 | T7: =IF(MONTH(A7)=2,IF((ISBLANK(C7)),0,(M7)),"0") -> 0 | U7: =IF(MONTH(A7)=3,IF((ISBLANK(B7)),0,(M7)),"0") -> 0 | V7: =IF(MONTH(A7)=3,IF((ISBLANK(C7)),0,(M7)),"0") -> 0 | W7: =IF(MONTH(A7)=4,IF((ISBLANK(B7)),0,(M7)),"0") -> 19125 | X7: =IF(MONTH(A7)=4,IF((ISBLANK(C7)),0,(M7)),"0") -> 0 | Y7: =IF(MONTH(A7)=5,IF((ISBLANK(B7)),0,(M7)),"0") -> 0 | Z7: =IF(MONTH(A7)=5,IF((ISBLANK(C7)),0,(M7)),"0") -> 0 | AA7: =IF(MONTH(A7)=6,IF((ISBLANK(B7)),0,(M7)),"0") -> 0 | AB7: =IF(MONTH(A7)=6,IF((ISBLANK(C7)),0,(M7)),"0") -> 0 | AC7: =IF(MONTH(A7)=7,IF((ISBLANK(B7)),0,(M7)),"0") -> 0 | AD7: =IF(MONTH(A7)=7,IF((ISBLANK(C7)),0,(M7)),"0") -> 0 | AE7: =IF(MONTH(A7)=8,IF((ISBLANK(B7)),0,(M7)),"0") -> 0 | AF7: =IF(MONTH(A7)=8,IF((ISBLANK(C7)),0,(M7)),"0") -> 0 | AG7: =IF(MONTH(A7)=9,IF((ISBLANK(B7)),0,(M7)),"0") -> 0 | AH7: =IF(MONTH(A7)=9,IF((ISBLANK(C7)),0,(M7)),"0") -> 0 | AI7: =IF(MONTH(A7)=10,IF((ISBLANK(B7)),0,(M7)),"0") -> 0 | AJ7: =IF(MONTH(A7)=10,IF((ISBLANK(C7)),0,(M7)),"0") -> 0 | AK7: =IF(MONTH(A7)=11,IF((ISBLANK(B7)),0,(M7)),"0") -> 0 | AL7: =IF(MONTH(A7)=11,IF((ISBLANK(C7)),0,(M7)),"0") -> 0 | AM7: =IF(MONTH(A7)=12,IF((ISBLANK(B7)),0,(M7)),"0") -> 0 | AN7: =IF(MONTH(A7)=12,IF((ISBLANK(C7)),0,(M7)),"0") -> 0
A8: 45758 | C8: 1 | D8: Rotary | F8: Doug Church | G8: 5713 15th Rd N, Arlington, VA 22205 | H8: 1350000 | I8: 1300000 | J8: 0.03 | K8: =IF(ISBLANK(A8),"",(I8*J8)) -> 39000 | M8: =IF((ISBLANK(A8)),"",'Fee calc_closed Transactions'!F8) -> 33150 | N8: =IF(K8="","",'Fee calc_closed Transactions'!G8) -> 5850 | P8: =IF(ISBLANK(A8),"0",I8) -> 1300000 | Q8: =IF(MONTH(A8)=1,IF((ISBLANK(B8)),0,(M8)),"0") -> 0 | R8: =IF(MONTH(A8)=1,IF((ISBLANK(C8)),0,(M8)),"0") -> 0 | S8: =IF(MONTH(A8)=2,IF((ISBLANK(B8)),0,(M8)),"0") -> 0 | T8: =IF(MONTH(A8)=2,IF((ISBLANK(C8)),0,(M8)),"0") -> 0 | U8: =IF(MONTH(A8)=3,IF((ISBLANK(B8)),0,(M8)),"0") -> 0 | V8: =IF(MONTH(A8)=3,IF((ISBLANK(C8)),0,(M8)),"0") -> 0 | W8: =IF(MONTH(A8)=4,IF((ISBLANK(B8)),0,(M8)),"0") -> 0 | X8: =IF(MONTH(A8)=4,IF((ISBLANK(C8)),0,(M8)),"0") -> 33150 | Y8: =IF(MONTH(A8)=5,IF((ISBLANK(B8)),0,(M8)),"0") -> 0 | Z8: =IF(MONTH(A8)=5,IF((ISBLANK(C8)),0,(M8)),"0") -> 0 | AA8: =IF(MONTH(A8)=6,IF((ISBLANK(B8)),0,(M8)),"0") -> 0 | AB8: =IF(MONTH(A8)=6,IF((ISBLANK(C8)),0,(M8)),"0") -> 0 | AC8: =IF(MONTH(A8)=7,IF((ISBLANK(B8)),0,(M8)),"0") -> 0 | AD8: =IF(MONTH(A8)=7,IF((ISBLANK(C8)),0,(M8)),"0") -> 0 | AE8: =IF(MONTH(A8)=8,IF((ISBLANK(B8)),0,(M8)),"0") -> 0 | AF8: =IF(MONTH(A8)=8,IF((ISBLANK(C8)),0,(M8)),"0") -> 0 | AG8: =IF(MONTH(A8)=9,IF((ISBLANK(B8)),0,(M8)),"0") -> 0 | AH8: =IF(MONTH(A8)=9,IF((ISBLANK(C8)),0,(M8)),"0") -> 0 | AI8: =IF(MONTH(A8)=10,IF((ISBLANK(B8)),0,(M8)),"0") -> 0 | AJ8: =IF(MONTH(A8)=10,IF((ISBLANK(C8)),0,(M8)),"0") -> 0 | AK8: =IF(MONTH(A8)=11,IF((ISBLANK(B8)),0,(M8)),"0") -> 0 | AL8: =IF(MONTH(A8)=11,IF((ISBLANK(C8)),0,(M8)),"0") -> 0 | AM8: =IF(MONTH(A8)=12,IF((ISBLANK(B8)),0,(M8)),"0") -> 0 | AN8: =IF(MONTH(A8)=12,IF((ISBLANK(C8)),0,(M8)),"0") -> 0
A9: 45828 | B9: 1 | C9: 1 | D9: CFCC | F9: Ashraf Kadri | G9: 901 Vista Terrace, Blacksburg, VA 24060 | I9: 390000 | J9: 0.0075 | K9: =IF(ISBLANK(A9),"",(I9*J9)) -> 2925 | M9: =IF((ISBLANK(A9)),"",'Fee calc_closed Transactions'!F9) -> 2486.25 | N9: =IF(K9="","",'Fee calc_closed Transactions'!G9) -> 438.75 | P9: =IF(ISBLANK(A9),"0",I9) -> 390000 | Q9: =IF(MONTH(A9)=1,IF((ISBLANK(B9)),0,(M9)),"0") -> 0 | R9: =IF(MONTH(A9)=1,IF((ISBLANK(C9)),0,(M9)),"0") -> 0 | S9: =IF(MONTH(A9)=2,IF((ISBLANK(B9)),0,(M9)),"0") -> 0 | T9: =IF(MONTH(A9)=2,IF((ISBLANK(C9)),0,(M9)),"0") -> 0 | U9: =IF(MONTH(A9)=3,IF((ISBLANK(B9)),0,(M9)),"0") -> 0 | V9: =IF(MONTH(A9)=3,IF((ISBLANK(C9)),0,(M9)),"0") -> 0 | W9: =IF(MONTH(A9)=4,IF((ISBLANK(B9)),0,(M9)),"0") -> 0 | X9: =IF(MONTH(A9)=4,IF((ISBLANK(C9)),0,(M9)),"0") -> 0 | Y9: =IF(MONTH(A9)=5,IF((ISBLANK(B9)),0,(M9)),"0") -> 0 | Z9: =IF(MONTH(A9)=5,IF((ISBLANK(C9)),0,(M9)),"0") -> 0 | AA9: =IF(MONTH(A9)=6,IF((ISBLANK(B9)),0,(M9)),"0") -> 2486.25 | AB9: =IF(MONTH(A9)=6,IF((ISBLANK(C9)),0,(M9)),"0") -> 2486.25 | AC9: =IF(MONTH(A9)=7,IF((ISBLANK(B9)),0,(M9)),"0") -> 0 | AD9: =IF(MONTH(A9)=7,IF((ISBLANK(C9)),0,(M9)),"0") -> 0 | AE9: =IF(MONTH(A9)=8,IF((ISBLANK(B9)),0,(M9)),"0") -> 0 | AF9: =IF(MONTH(A9)=8,IF((ISBLANK(C9)),0,(M9)),"0") -> 0 | AG9: =IF(MONTH(A9)=9,IF((ISBLANK(B9)),0,(M9)),"0") -> 0 | AH9: =IF(MONTH(A9)=9,IF((ISBLANK(C9)),0,(M9)),"0") -> 0 | AI9: =IF(MONTH(A9)=10,IF((ISBLANK(B9)),0,(M9)),"0") -> 0 | AJ9: =IF(MONTH(A9)=10,IF((ISBLANK(C9)),0,(M9)),"0") -> 0 | AK9: =IF(MONTH(A9)=11,IF((ISBLANK(B9)),0,(M9)),"0") -> 0 | AL9: =IF(MONTH(A9)=11,IF((ISBLANK(C9)),0,(M9)),"0") -> 0 | AM9: =IF(MONTH(A9)=12,IF((ISBLANK(B9)),0,(M9)),"0") -> 0 | AN9: =IF(MONTH(A9)=12,IF((ISBLANK(C9)),0,(M9)),"0") -> 0
A10: 45838 | C10: 1 | D10: my property | F10: Nathan Desnoyers | G10: 14451 Saguaro Pl, Centreville, VA 20121 | H10: 345000 | I10: 365000 | J10: 0 | K10: =IF(ISBLANK(A10),"",(I10*J10)) -> 0 | M10: =IF((ISBLANK(A10)),"",'Fee calc_closed Transactions'!F10) -> 0 | N10: =IF(K10="","",'Fee calc_closed Transactions'!G10) -> 0 | P10: =IF(ISBLANK(A10),"0",I10) -> 365000 | Q10: =IF(MONTH(A10)=1,IF((ISBLANK(B10)),0,(M10)),"0") -> 0 | R10: =IF(MONTH(A10)=1,IF((ISBLANK(C10)),0,(M10)),"0") -> 0 | S10: =IF(MONTH(A10)=2,IF((ISBLANK(B10)),0,(M10)),"0") -> 0 | T10: =IF(MONTH(A10)=2,IF((ISBLANK(C10)),0,(M10)),"0") -> 0 | U10: =IF(MONTH(A10)=3,IF((ISBLANK(B10)),0,(M10)),"0") -> 0 | V10: =IF(MONTH(A10)=3,IF((ISBLANK(C10)),0,(M10)),"0") -> 0 | W10: =IF(MONTH(A10)=4,IF((ISBLANK(B10)),0,(M10)),"0") -> 0 | X10: =IF(MONTH(A10)=4,IF((ISBLANK(C10)),0,(M10)),"0") -> 0 | Y10: =IF(MONTH(A10)=5,IF((ISBLANK(B10)),0,(M10)),"0") -> 0 | Z10: =IF(MONTH(A10)=5,IF((ISBLANK(C10)),0,(M10)),"0") -> 0 | AA10: =IF(MONTH(A10)=6,IF((ISBLANK(B10)),0,(M10)),"0") -> 0 | AB10: =IF(MONTH(A10)=6,IF((ISBLANK(C10)),0,(M10)),"0") -> 0 | AC10: =IF(MONTH(A10)=7,IF((ISBLANK(B10)),0,(M10)),"0") -> 0 | AD10: =IF(MONTH(A10)=7,IF((ISBLANK(C10)),0,(M10)),"0") -> 0 | AE10: =IF(MONTH(A10)=8,IF((ISBLANK(B10)),0,(M10)),"0") -> 0 | AF10: =IF(MONTH(A10)=8,IF((ISBLANK(C10)),0,(M10)),"0") -> 0 | AG10: =IF(MONTH(A10)=9,IF((ISBLANK(B10)),0,(M10)),"0") -> 0 | AH10: =IF(MONTH(A10)=9,IF((ISBLANK(C10)),0,(M10)),"0") -> 0 | AI10: =IF(MONTH(A10)=10,IF((ISBLANK(B10)),0,(M10)),"0") -> 0 | AJ10: =IF(MONTH(A10)=10,IF((ISBLANK(C10)),0,(M10)),"0") -> 0 | AK10: =IF(MONTH(A10)=11,IF((ISBLANK(B10)),0,(M10)),"0") -> 0 | AL10: =IF(MONTH(A10)=11,IF((ISBLANK(C10)),0,(M10)),"0") -> 0 | AM10: =IF(MONTH(A10)=12,IF((ISBLANK(B10)),0,(M10)),"0") -> 0 | AN10: =IF(MONTH(A10)=12,IF((ISBLANK(C10)),0,(M10)),"0") -> 0
A11: 45839 | B11: 1 | D11: BNI | F11: Saria Alshaikhalia | G11: 2833 Kalmi Lee Ct,#302 Falls Church, VA 22042 | H11: 2195 | I11: 2195 | J11: 0.25 | K11: =IF(ISBLANK(A11),"",(I11*J11)) -> 548.75 | M11: =IF((ISBLANK(A11)),"",'Fee calc_closed Transactions'!F11) -> 466.4375 | N11: =IF(K11="","",'Fee calc_closed Transactions'!G11) -> 82.3125 | P11: =IF(ISBLANK(A11),"0",I11) -> 2195 | Q11: =IF(MONTH(A11)=1,IF((ISBLANK(B11)),0,(M11)),"0") -> 0 | R11: =IF(MONTH(A11)=1,IF((ISBLANK(C11)),0,(M11)),"0") -> 0 | S11: =IF(MONTH(A11)=2,IF((ISBLANK(B11)),0,(M11)),"0") -> 0 | T11: =IF(MONTH(A11)=2,IF((ISBLANK(C11)),0,(M11)),"0") -> 0 | U11: =IF(MONTH(A11)=3,IF((ISBLANK(B11)),0,(M11)),"0") -> 0 | V11: =IF(MONTH(A11)=3,IF((ISBLANK(C11)),0,(M11)),"0") -> 0 | W11: =IF(MONTH(A11)=4,IF((ISBLANK(B11)),0,(M11)),"0") -> 0 | X11: =IF(MONTH(A11)=4,IF((ISBLANK(C11)),0,(M11)),"0") -> 0 | Y11: =IF(MONTH(A11)=5,IF((ISBLANK(B11)),0,(M11)),"0") -> 0 | Z11: =IF(MONTH(A11)=5,IF((ISBLANK(C11)),0,(M11)),"0") -> 0 | AA11: =IF(MONTH(A11)=6,IF((ISBLANK(B11)),0,(M11)),"0") -> 0 | AB11: =IF(MONTH(A11)=6,IF((ISBLANK(C11)),0,(M11)),"0") -> 0 | AC11: =IF(MONTH(A11)=7,IF((ISBLANK(B11)),0,(M11)),"0") -> 466.4375 | AD11: =IF(MONTH(A11)=7,IF((ISBLANK(C11)),0,(M11)),"0") -> 0 | AE11: =IF(MONTH(A11)=8,IF((ISBLANK(B11)),0,(M11)),"0") -> 0 | AF11: =IF(MONTH(A11)=8,IF((ISBLANK(C11)),0,(M11)),"0") -> 0 | AG11: =IF(MONTH(A11)=9,IF((ISBLANK(B11)),0,(M11)),"0") -> 0 | AH11: =IF(MONTH(A11)=9,IF((ISBLANK(C11)),0,(M11)),"0") -> 0 | AI11: =IF(MONTH(A11)=10,IF((ISBLANK(B11)),0,(M11)),"0") -> 0 | AJ11: =IF(MONTH(A11)=10,IF((ISBLANK(C11)),0,(M11)),"0") -> 0 | AK11: =IF(MONTH(A11)=11,IF((ISBLANK(B11)),0,(M11)),"0") -> 0 | AL11: =IF(MONTH(A11)=11,IF((ISBLANK(C11)),0,(M11)),"0") -> 0 | AM11: =IF(MONTH(A11)=12,IF((ISBLANK(B11)),0,(M11)),"0") -> 0 | AN11: =IF(MONTH(A11)=12,IF((ISBLANK(C11)),0,(M11)),"0") -> 0
A12: 45839 | B12: 1 | D12: sign call | F12: Sneha Durgapal & Alex Hennessy | G12: 820 N Pollard #316, Arlington VA | H12: 3150 | I12: 3150 | J12: 0 | K12: =IF(ISBLANK(A12),"",(I12*J12)) -> 0 | M12: =IF((ISBLANK(A12)),"",'Fee calc_closed Transactions'!F12) -> 0 | N12: =IF(K12="","",'Fee calc_closed Transactions'!G12) -> 0 | P12: =IF(ISBLANK(A12),"0",I12) -> 3150 | Q12: =IF(MONTH(A12)=1,IF((ISBLANK(B12)),0,(M12)),"0") -> 0 | R12: =IF(MONTH(A12)=1,IF((ISBLANK(C12)),0,(M12)),"0") -> 0 | S12: =IF(MONTH(A12)=2,IF((ISBLANK(B12)),0,(M12)),"0") -> 0 | T12: =IF(MONTH(A12)=2,IF((ISBLANK(C12)),0,(M12)),"0") -> 0 | U12: =IF(MONTH(A12)=3,IF((ISBLANK(B12)),0,(M12)),"0") -> 0 | V12: =IF(MONTH(A12)=3,IF((ISBLANK(C12)),0,(M12)),"0") -> 0 | W12: =IF(MONTH(A12)=4,IF((ISBLANK(B12)),0,(M12)),"0") -> 0 | X12: =IF(MONTH(A12)=4,IF((ISBLANK(C12)),0,(M12)),"0") -> 0 | Y12: =IF(MONTH(A12)=5,IF((ISBLANK(B12)),0,(M12)),"0") -> 0 | Z12: =IF(MONTH(A12)=5,IF((ISBLANK(C12)),0,(M12)),"0") -> 0 | AA12: =IF(MONTH(A12)=6,IF((ISBLANK(B12)),0,(M12)),"0") -> 0 | AB12: =IF(MONTH(A12)=6,IF((ISBLANK(C12)),0,(M12)),"0") -> 0 | AC12: =IF(MONTH(A12)=7,IF((ISBLANK(B12)),0,(M12)),"0") -> 0 | AD12: =IF(MONTH(A12)=7,IF((ISBLANK(C12)),0,(M12)),"0") -> 0 | AE12: =IF(MONTH(A12)=8,IF((ISBLANK(B12)),0,(M12)),"0") -> 0 | AF12: =IF(MONTH(A12)=8,IF((ISBLANK(C12)),0,(M12)),"0") -> 0 | AG12: =IF(MONTH(A12)=9,IF((ISBLANK(B12)),0,(M12)),"0") -> 0 | AH12: =IF(MONTH(A12)=9,IF((ISBLANK(C12)),0,(M12)),"0") -> 0 | AI12: =IF(MONTH(A12)=10,IF((ISBLANK(B12)),0,(M12)),"0") -> 0 | AJ12: =IF(MONTH(A12)=10,IF((ISBLANK(C12)),0,(M12)),"0") -> 0 | AK12: =IF(MONTH(A12)=11,IF((ISBLANK(B12)),0,(M12)),"0") -> 0 | AL12: =IF(MONTH(A12)=11,IF((ISBLANK(C12)),0,(M12)),"0") -> 0 | AM12: =IF(MONTH(A12)=12,IF((ISBLANK(B12)),0,(M12)),"0") -> 0 | AN12: =IF(MONTH(A12)=12,IF((ISBLANK(C12)),0,(M12)),"0") -> 0
A13: 45845 | B13: 1 | D13: Rotary | F13: Jared Traggic & Kiana Spearman | G13: 4200 MOZART BRIGADE LANE # 4200C, FAIRFAX, VA 22033 | H13: 2400 | I13: 2400 | J13: 0.25 | K13: =IF(ISBLANK(A13),"",(I13*J13)) -> 600 | M13: =IF((ISBLANK(A13)),"",'Fee calc_closed Transactions'!F13) -> 510 | N13: =IF(K13="","",'Fee calc_closed Transactions'!G13) -> 90 | P13: =IF(ISBLANK(A13),"0",I13) -> 2400 | Q13: =IF(MONTH(A13)=1,IF((ISBLANK(B13)),0,(M13)),"0") -> 0 | R13: =IF(MONTH(A13)=1,IF((ISBLANK(C13)),0,(M13)),"0") -> 0 | S13: =IF(MONTH(A13)=2,IF((ISBLANK(B13)),0,(M13)),"0") -> 0 | T13: =IF(MONTH(A13)=2,IF((ISBLANK(C13)),0,(M13)),"0") -> 0 | U13: =IF(MONTH(A13)=3,IF((ISBLANK(B13)),0,(M13)),"0") -> 0 | V13: =IF(MONTH(A13)=3,IF((ISBLANK(C13)),0,(M13)),"0") -> 0 | W13: =IF(MONTH(A13)=4,IF((ISBLANK(B13)),0,(M13)),"0") -> 0 | X13: =IF(MONTH(A13)=4,IF((ISBLANK(C13)),0,(M13)),"0") -> 0 | Y13: =IF(MONTH(A13)=5,IF((ISBLANK(B13)),0,(M13)),"0") -> 0 | Z13: =IF(MONTH(A13)=5,IF((ISBLANK(C13)),0,(M13)),"0") -> 0 | AA13: =IF(MONTH(A13)=6,IF((ISBLANK(B13)),0,(M13)),"0") -> 0 | AB13: =IF(MONTH(A13)=6,IF((ISBLANK(C13)),0,(M13)),"0") -> 0 | AC13: =IF(MONTH(A13)=7,IF((ISBLANK(B13)),0,(M13)),"0") -> 510 | AD13: =IF(MONTH(A13)=7,IF((ISBLANK(C13)),0,(M13)),"0") -> 0 | AE13: =IF(MONTH(A13)=8,IF((ISBLANK(B13)),0,(M13)),"0") -> 0 | AF13: =IF(MONTH(A13)=8,IF((ISBLANK(C13)),0,(M13)),"0") -> 0 | AG13: =IF(MONTH(A13)=9,IF((ISBLANK(B13)),0,(M13)),"0") -> 0 | AH13: =IF(MONTH(A13)=9,IF((ISBLANK(C13)),0,(M13)),"0") -> 0 | AI13: =IF(MONTH(A13)=10,IF((ISBLANK(B13)),0,(M13)),"0") -> 0 | AJ13: =IF(MONTH(A13)=10,IF((ISBLANK(C13)),0,(M13)),"0") -> 0 | AK13: =IF(MONTH(A13)=11,IF((ISBLANK(B13)),0,(M13)),"0") -> 0 | AL13: =IF(MONTH(A13)=11,IF((ISBLANK(C13)),0,(M13)),"0") -> 0 | AM13: =IF(MONTH(A13)=12,IF((ISBLANK(B13)),0,(M13)),"0") -> 0 | AN13: =IF(MONTH(A13)=12,IF((ISBLANK(C13)),0,(M13)),"0") -> 0
A14: 45853 | B14: 1 | D14: ninja referral | F14: Kristine & Ken Delos Reyes | G14: 8993 Katherine Johnson Dr, Manassas, VA 20109 | H14: 665280 | I14: 665280 | J14: 0.00901876 | K14: =IF(ISBLANK(A14),"",(I14*J14)) -> 6000.0007 | L14: 1800 | M14: =IF((ISBLANK(A14)),"",'Fee calc_closed Transactions'!F14) -> 3570.0006 | N14: =IF(K14="","",'Fee calc_closed Transactions'!G14) -> 630.0001 | P14: =IF(ISBLANK(A14),"0",I14) -> 665280 | Q14: =IF(MONTH(A14)=1,IF((ISBLANK(B14)),0,(M14)),"0") -> 0 | R14: =IF(MONTH(A14)=1,IF((ISBLANK(C14)),0,(M14)),"0") -> 0 | S14: =IF(MONTH(A14)=2,IF((ISBLANK(B14)),0,(M14)),"0") -> 0 | T14: =IF(MONTH(A14)=2,IF((ISBLANK(C14)),0,(M14)),"0") -> 0 | U14: =IF(MONTH(A14)=3,IF((ISBLANK(B14)),0,(M14)),"0") -> 0 | V14: =IF(MONTH(A14)=3,IF((ISBLANK(C14)),0,(M14)),"0") -> 0 | W14: =IF(MONTH(A14)=4,IF((ISBLANK(B14)),0,(M14)),"0") -> 0 | X14: =IF(MONTH(A14)=4,IF((ISBLANK(C14)),0,(M14)),"0") -> 0 | Y14: =IF(MONTH(A14)=5,IF((ISBLANK(B14)),0,(M14)),"0") -> 0 | Z14: =IF(MONTH(A14)=5,IF((ISBLANK(C14)),0,(M14)),"0") -> 0 | AA14: =IF(MONTH(A14)=6,IF((ISBLANK(B14)),0,(M14)),"0") -> 0 | AB14: =IF(MONTH(A14)=6,IF((ISBLANK(C14)),0,(M14)),"0") -> 0 | AC14: =IF(MONTH(A14)=7,IF((ISBLANK(B14)),0,(M14)),"0") -> 3570.0006 | AD14: =IF(MONTH(A14)=7,IF((ISBLANK(C14)),0,(M14)),"0") -> 0 | AE14: =IF(MONTH(A14)=8,IF((ISBLANK(B14)),0,(M14)),"0") -> 0 | AF14: =IF(MONTH(A14)=8,IF((ISBLANK(C14)),0,(M14)),"0") -> 0 | AG14: =IF(MONTH(A14)=9,IF((ISBLANK(B14)),0,(M14)),"0") -> 0 | AH14: =IF(MONTH(A14)=9,IF((ISBLANK(C14)),0,(M14)),"0") -> 0 | AI14: =IF(MONTH(A14)=10,IF((ISBLANK(B14)),0,(M14)),"0") -> 0 | AJ14: =IF(MONTH(A14)=10,IF((ISBLANK(C14)),0,(M14)),"0") -> 0 | AK14: =IF(MONTH(A14)=11,IF((ISBLANK(B14)),0,(M14)),"0") -> 0 | AL14: =IF(MONTH(A14)=11,IF((ISBLANK(C14)),0,(M14)),"0") -> 0 | AM14: =IF(MONTH(A14)=12,IF((ISBLANK(B14)),0,(M14)),"0") -> 0 | AN14: =IF(MONTH(A14)=12,IF((ISBLANK(C14)),0,(M14)),"0") -> 0
A15: 45884 | B15: 1 | C15: 1 | D15: realtor referral | F15: Anne Duffy, Joshua Foote, Kate McCusker | G15: 926 N Edgewood St #2, Arlington, VA 22201 | H15: 3295 | I15: 3295 | J15: 1 | K15: =IF(ISBLANK(A15),"",(I15*J15)) -> 3295 | L15: 823.75 | M15: =IF((ISBLANK(A15)),"",'Fee calc_closed Transactions'!F15) -> 2100.5625 | N15: =IF(K15="","",'Fee calc_closed Transactions'!G15) -> 370.6875 | P15: =IF(ISBLANK(A15),"0",I15) -> 3295 | Q15: =IF(MONTH(A15)=1,IF((ISBLANK(B15)),0,(M15)),"0") -> 0 | R15: =IF(MONTH(A15)=1,IF((ISBLANK(C15)),0,(M15)),"0") -> 0 | S15: =IF(MONTH(A15)=2,IF((ISBLANK(B15)),0,(M15)),"0") -> 0 | T15: =IF(MONTH(A15)=2,IF((ISBLANK(C15)),0,(M15)),"0") -> 0 | U15: =IF(MONTH(A15)=3,IF((ISBLANK(B15)),0,(M15)),"0") -> 0 | V15: =IF(MONTH(A15)=3,IF((ISBLANK(C15)),0,(M15)),"0") -> 0 | W15: =IF(MONTH(A15)=4,IF((ISBLANK(B15)),0,(M15)),"0") -> 0 | X15: =IF(MONTH(A15)=4,IF((ISBLANK(C15)),0,(M15)),"0") -> 0 | Y15: =IF(MONTH(A15)=5,IF((ISBLANK(B15)),0,(M15)),"0") -> 0 | Z15: =IF(MONTH(A15)=5,IF((ISBLANK(C15)),0,(M15)),"0") -> 0 | AA15: =IF(MONTH(A15)=6,IF((ISBLANK(B15)),0,(M15)),"0") -> 0 | AB15: =IF(MONTH(A15)=6,IF((ISBLANK(C15)),0,(M15)),"0") -> 0 | AC15: =IF(MONTH(A15)=7,IF((ISBLANK(B15)),0,(M15)),"0") -> 0 | AD15: =IF(MONTH(A15)=7,IF((ISBLANK(C15)),0,(M15)),"0") -> 0 | AE15: =IF(MONTH(A15)=8,IF((ISBLANK(B15)),0,(M15)),"0") -> 2100.5625 | AF15: =IF(MONTH(A15)=8,IF((ISBLANK(C15)),0,(M15)),"0") -> 2100.5625 | AG15: =IF(MONTH(A15)=9,IF((ISBLANK(B15)),0,(M15)),"0") -> 0 | AH15: =IF(MONTH(A15)=9,IF((ISBLANK(C15)),0,(M15)),"0") -> 0 | AI15: =IF(MONTH(A15)=10,IF((ISBLANK(B15)),0,(M15)),"0") -> 0 | AJ15: =IF(MONTH(A15)=10,IF((ISBLANK(C15)),0,(M15)),"0") -> 0 | AK15: =IF(MONTH(A15)=11,IF((ISBLANK(B15)),0,(M15)),"0") -> 0 | AL15: =IF(MONTH(A15)=11,IF((ISBLANK(C15)),0,(M15)),"0") -> 0 | AM15: =IF(MONTH(A15)=12,IF((ISBLANK(B15)),0,(M15)),"0") -> 0 | AN15: =IF(MONTH(A15)=12,IF((ISBLANK(C15)),0,(M15)),"0") -> 0
A16: 45903 | B16: 1 | D16: wife | F16: Cintia Samaha Desnoyers | G16: 14552 Woodgate Manor Pl, Centreville, VA 20120 | H16: 599990 | I16: 615000 | J16: 0 | K16: =IF(ISBLANK(A16),"",(I16*J16)) -> 0 | M16: =IF((ISBLANK(A16)),"",'Fee calc_closed Transactions'!F16) -> 0 | N16: =IF(K16="","",'Fee calc_closed Transactions'!G16) -> 0 | P16: =IF(ISBLANK(A16),"0",I16) -> 615000 | Q16: =IF(MONTH(A16)=1,IF((ISBLANK(B16)),0,(M16)),"0") -> 0 | R16: =IF(MONTH(A16)=1,IF((ISBLANK(C16)),0,(M16)),"0") -> 0 | S16: =IF(MONTH(A16)=2,IF((ISBLANK(B16)),0,(M16)),"0") -> 0 | T16: =IF(MONTH(A16)=2,IF((ISBLANK(C16)),0,(M16)),"0") -> 0 | U16: =IF(MONTH(A16)=3,IF((ISBLANK(B16)),0,(M16)),"0") -> 0 | V16: =IF(MONTH(A16)=3,IF((ISBLANK(C16)),0,(M16)),"0") -> 0 | W16: =IF(MONTH(A16)=4,IF((ISBLANK(B16)),0,(M16)),"0") -> 0 | X16: =IF(MONTH(A16)=4,IF((ISBLANK(C16)),0,(M16)),"0") -> 0 | Y16: =IF(MONTH(A16)=5,IF((ISBLANK(B16)),0,(M16)),"0") -> 0 | Z16: =IF(MONTH(A16)=5,IF((ISBLANK(C16)),0,(M16)),"0") -> 0 | AA16: =IF(MONTH(A16)=6,IF((ISBLANK(B16)),0,(M16)),"0") -> 0 | AB16: =IF(MONTH(A16)=6,IF((ISBLANK(C16)),0,(M16)),"0") -> 0 | AC16: =IF(MONTH(A16)=7,IF((ISBLANK(B16)),0,(M16)),"0") -> 0 | AD16: =IF(MONTH(A16)=7,IF((ISBLANK(C16)),0,(M16)),"0") -> 0 | AE16: =IF(MONTH(A16)=8,IF((ISBLANK(B16)),0,(M16)),"0") -> 0 | AF16: =IF(MONTH(A16)=8,IF((ISBLANK(C16)),0,(M16)),"0") -> 0 | AG16: =IF(MONTH(A16)=9,IF((ISBLANK(B16)),0,(M16)),"0") -> 0 | AH16: =IF(MONTH(A16)=9,IF((ISBLANK(C16)),0,(M16)),"0") -> 0 | AI16: =IF(MONTH(A16)=10,IF((ISBLANK(B16)),0,(M16)),"0") -> 0 | AJ16: =IF(MONTH(A16)=10,IF((ISBLANK(C16)),0,(M16)),"0") -> 0 | AK16: =IF(MONTH(A16)=11,IF((ISBLANK(B16)),0,(M16)),"0") -> 0 | AL16: =IF(MONTH(A16)=11,IF((ISBLANK(C16)),0,(M16)),"0") -> 0 | AM16: =IF(MONTH(A16)=12,IF((ISBLANK(B16)),0,(M16)),"0") -> 0 | AN16: =IF(MONTH(A16)=12,IF((ISBLANK(C16)),0,(M16)),"0") -> 0
A17: 45910 | C17: 1 | D17: SOI | F17: Ashleigh Verma & Tapinder Garcha | G17: 2820 Hokie Ln, Alexandria, VA 22314 | H17: 780000 | I17: 770000 | J17: 0.02 | K17: =IF(ISBLANK(A17),"",(I17*J17)) -> 15400 | M17: =IF((ISBLANK(A17)),"",'Fee calc_closed Transactions'!F17) -> 13090 | N17: =IF(K17="","",'Fee calc_closed Transactions'!G17) -> 2310 | P17: =IF(ISBLANK(A17),"0",I17) -> 770000 | Q17: =IF(MONTH(A17)=1,IF((ISBLANK(B17)),0,(M17)),"0") -> 0 | R17: =IF(MONTH(A17)=1,IF((ISBLANK(C17)),0,(M17)),"0") -> 0 | S17: =IF(MONTH(A17)=2,IF((ISBLANK(B17)),0,(M17)),"0") -> 0 | T17: =IF(MONTH(A17)=2,IF((ISBLANK(C17)),0,(M17)),"0") -> 0 | U17: =IF(MONTH(A17)=3,IF((ISBLANK(B17)),0,(M17)),"0") -> 0 | V17: =IF(MONTH(A17)=3,IF((ISBLANK(C17)),0,(M17)),"0") -> 0 | W17: =IF(MONTH(A17)=4,IF((ISBLANK(B17)),0,(M17)),"0") -> 0 | X17: =IF(MONTH(A17)=4,IF((ISBLANK(C17)),0,(M17)),"0") -> 0 | Y17: =IF(MONTH(A17)=5,IF((ISBLANK(B17)),0,(M17)),"0") -> 0 | Z17: =IF(MONTH(A17)=5,IF((ISBLANK(C17)),0,(M17)),"0") -> 0 | AA17: =IF(MONTH(A17)=6,IF((ISBLANK(B17)),0,(M17)),"0") -> 0 | AB17: =IF(MONTH(A17)=6,IF((ISBLANK(C17)),0,(M17)),"0") -> 0 | AC17: =IF(MONTH(A17)=7,IF((ISBLANK(B17)),0,(M17)),"0") -> 0 | AD17: =IF(MONTH(A17)=7,IF((ISBLANK(C17)),0,(M17)),"0") -> 0 | AE17: =IF(MONTH(A17)=8,IF((ISBLANK(B17)),0,(M17)),"0") -> 0 | AF17: =IF(MONTH(A17)=8,IF((ISBLANK(C17)),0,(M17)),"0") -> 0 | AG17: =IF(MONTH(A17)=9,IF((ISBLANK(B17)),0,(M17)),"0") -> 0 | AH17: =IF(MONTH(A17)=9,IF((ISBLANK(C17)),0,(M17)),"0") -> 13090 | AI17: =IF(MONTH(A17)=10,IF((ISBLANK(B17)),0,(M17)),"0") -> 0 | AJ17: =IF(MONTH(A17)=10,IF((ISBLANK(C17)),0,(M17)),"0") -> 0 | AK17: =IF(MONTH(A17)=11,IF((ISBLANK(B17)),0,(M17)),"0") -> 0 | AL17: =IF(MONTH(A17)=11,IF((ISBLANK(C17)),0,(M17)),"0") -> 0 | AM17: =IF(MONTH(A17)=12,IF((ISBLANK(B17)),0,(M17)),"0") -> 0 | AN17: =IF(MONTH(A17)=12,IF((ISBLANK(C17)),0,(M17)),"0") -> 0
A18: 45920 | C18: 1 | D18: wife | F18: Cintia Samaha Desnoyers | G18: 11122 Rock Garden Dr, Fairfax, 22030 | H18: 2300 | I18: 2400 | J18: 0 | K18: =IF(ISBLANK(A18),"",(I18*J18)) -> 0 | M18: =IF((ISBLANK(A18)),"",'Fee calc_closed Transactions'!F18) -> 0 | N18: =IF(K18="","",'Fee calc_closed Transactions'!G18) -> 0 | P18: =IF(ISBLANK(A18),"0",I18) -> 2400 | Q18: =IF(MONTH(A18)=1,IF((ISBLANK(B18)),0,(M18)),"0") -> 0 | R18: =IF(MONTH(A18)=1,IF((ISBLANK(C18)),0,(M18)),"0") -> 0 | S18: =IF(MONTH(A18)=2,IF((ISBLANK(B18)),0,(M18)),"0") -> 0 | T18: =IF(MONTH(A18)=2,IF((ISBLANK(C18)),0,(M18)),"0") -> 0 | U18: =IF(MONTH(A18)=3,IF((ISBLANK(B18)),0,(M18)),"0") -> 0 | V18: =IF(MONTH(A18)=3,IF((ISBLANK(C18)),0,(M18)),"0") -> 0 | W18: =IF(MONTH(A18)=4,IF((ISBLANK(B18)),0,(M18)),"0") -> 0 | X18: =IF(MONTH(A18)=4,IF((ISBLANK(C18)),0,(M18)),"0") -> 0 | Y18: =IF(MONTH(A18)=5,IF((ISBLANK(B18)),0,(M18)),"0") -> 0 | Z18: =IF(MONTH(A18)=5,IF((ISBLANK(C18)),0,(M18)),"0") -> 0 | AA18: =IF(MONTH(A18)=6,IF((ISBLANK(B18)),0,(M18)),"0") -> 0 | AB18: =IF(MONTH(A18)=6,IF((ISBLANK(C18)),0,(M18)),"0") -> 0 | AC18: =IF(MONTH(A18)=7,IF((ISBLANK(B18)),0,(M18)),"0") -> 0 | AD18: =IF(MONTH(A18)=7,IF((ISBLANK(C18)),0,(M18)),"0") -> 0 | AE18: =IF(MONTH(A18)=8,IF((ISBLANK(B18)),0,(M18)),"0") -> 0 | AF18: =IF(MONTH(A18)=8,IF((ISBLANK(C18)),0,(M18)),"0") -> 0 | AG18: =IF(MONTH(A18)=9,IF((ISBLANK(B18)),0,(M18)),"0") -> 0 | AH18: =IF(MONTH(A18)=9,IF((ISBLANK(C18)),0,(M18)),"0") -> 0 | AI18: =IF(MONTH(A18)=10,IF((ISBLANK(B18)),0,(M18)),"0") -> 0 | AJ18: =IF(MONTH(A18)=10,IF((ISBLANK(C18)),0,(M18)),"0") -> 0 | AK18: =IF(MONTH(A18)=11,IF((ISBLANK(B18)),0,(M18)),"0") -> 0 | AL18: =IF(MONTH(A18)=11,IF((ISBLANK(C18)),0,(M18)),"0") -> 0 | AM18: =IF(MONTH(A18)=12,IF((ISBLANK(B18)),0,(M18)),"0") -> 0 | AN18: =IF(MONTH(A18)=12,IF((ISBLANK(C18)),0,(M18)),"0") -> 0
A19: 45981 | C19: 1 | D19: wife | F19: Noel Contreras | G19: 14552 Woodgate Manor Pl, Centreville, VA 20120 | H19: 1500 | I19: 1500 | J19: 0 | K19: =IF(ISBLANK(A19),"",(I19*J19)) -> 0 | M19: =IF((ISBLANK(A19)),"",'Fee calc_closed Transactions'!F19) -> 0 | N19: =IF(K19="","",'Fee calc_closed Transactions'!G19) -> 0 | P19: =IF(ISBLANK(A19),"0",I19) -> 1500 | Q19: =IF(MONTH(A19)=1,IF((ISBLANK(B19)),0,(M19)),"0") -> 0 | R19: =IF(MONTH(A19)=1,IF((ISBLANK(C19)),0,(M19)),"0") -> 0 | S19: =IF(MONTH(A19)=2,IF((ISBLANK(B19)),0,(M19)),"0") -> 0 | T19: =IF(MONTH(A19)=2,IF((ISBLANK(C19)),0,(M19)),"0") -> 0 | U19: =IF(MONTH(A19)=3,IF((ISBLANK(B19)),0,(M19)),"0") -> 0 | V19: =IF(MONTH(A19)=3,IF((ISBLANK(C19)),0,(M19)),"0") -> 0 | W19: =IF(MONTH(A19)=4,IF((ISBLANK(B19)),0,(M19)),"0") -> 0 | X19: =IF(MONTH(A19)=4,IF((ISBLANK(C19)),0,(M19)),"0") -> 0 | Y19: =IF(MONTH(A19)=5,IF((ISBLANK(B19)),0,(M19)),"0") -> 0 | Z19: =IF(MONTH(A19)=5,IF((ISBLANK(C19)),0,(M19)),"0") -> 0 | AA19: =IF(MONTH(A19)=6,IF((ISBLANK(B19)),0,(M19)),"0") -> 0 | AB19: =IF(MONTH(A19)=6,IF((ISBLANK(C19)),0,(M19)),"0") -> 0 | AC19: =IF(MONTH(A19)=7,IF((ISBLANK(B19)),0,(M19)),"0") -> 0 | AD19: =IF(MONTH(A19)=7,IF((ISBLANK(C19)),0,(M19)),"0") -> 0 | AE19: =IF(MONTH(A19)=8,IF((ISBLANK(B19)),0,(M19)),"0") -> 0 | AF19: =IF(MONTH(A19)=8,IF((ISBLANK(C19)),0,(M19)),"0") -> 0 | AG19: =IF(MONTH(A19)=9,IF((ISBLANK(B19)),0,(M19)),"0") -> 0 | AH19: =IF(MONTH(A19)=9,IF((ISBLANK(C19)),0,(M19)),"0") -> 0 | AI19: =IF(MONTH(A19)=10,IF((ISBLANK(B19)),0,(M19)),"0") -> 0 | AJ19: =IF(MONTH(A19)=10,IF((ISBLANK(C19)),0,(M19)),"0") -> 0 | AK19: =IF(MONTH(A19)=11,IF((ISBLANK(B19)),0,(M19)),"0") -> 0 | AL19: =IF(MONTH(A19)=11,IF((ISBLANK(C19)),0,(M19)),"0") -> 0 | AM19: =IF(MONTH(A19)=12,IF((ISBLANK(B19)),0,(M19)),"0") -> 0 | AN19: =IF(MONTH(A19)=12,IF((ISBLANK(C19)),0,(M19)),"0") -> 0
